Task terminal.tasks.clean_orphan_session[01825f5a-f491-4e4d-a7e2-1a193b608b62] raised unexpected: OperationalError(2006, "Can't connect to MySQL server on '101.201.198.218' (51)")
Traceback (most recent call last):
  File "/Users/apple/Downloads/jumpserver-master/py3/lib/python3.6/site-packages/django/db/backends/base/base.py", line 216, in ensure_connection
    self.connect()
  File "/Users/apple/Downloads/jumpserver-master/py3/lib/python3.6/site-packages/django/db/backends/base/base.py", line 194, in connect
    self.connection = self.get_new_connection(conn_params)
  File "/Users/apple/Downloads/jumpserver-master/py3/lib/python3.6/site-packages/django/db/backends/mysql/base.py", line 227, in get_new_connection
    return Database.connect(**conn_params)
  File "/Users/apple/Downloads/jumpserver-master/py3/lib/python3.6/site-packages/MySQLdb/__init__.py", line 85, in Connect
    return Connection(*args, **kwargs)
  File "/Users/apple/Downloads/jumpserver-master/py3/lib/python3.6/site-packages/MySQLdb/connections.py", line 208, in __init__
    super(Connection, self).__init__(*args, **kwargs2)
_mysql_exceptions.OperationalError: (2006, "Can't connect to MySQL server on '101.201.198.218' (51)")

The above exception was the direct cause of the following exception:

Traceback (most recent call last):
  File "/Users/apple/Downloads/jumpserver-master/py3/lib/python3.6/site-packages/celery/app/trace.py", line 374, in trace_task
    R = retval = fun(*args, **kwargs)
  File "/Users/apple/Downloads/jumpserver-master/py3/lib/python3.6/site-packages/celery/app/trace.py", line 629, in __protected_call__
    return self.run(*args, **kwargs)
  File "/Users/apple/PycharmProjects/jumpserver/apps/ops/celery/decorator.py", line 81, in wrapper
    return func(*args, **kwargs)
  File "/Users/apple/PycharmProjects/jumpserver/apps/ops/celery/decorator.py", line 95, in decorate
    return func(*args, **kwargs)
  File "/Users/apple/PycharmProjects/jumpserver/apps/ops/celery/decorator.py", line 108, in decorate
    return func(*args, **kwargs)
  File "/Users/apple/PycharmProjects/jumpserver/apps/terminal/tasks.py", line 39, in clean_orphan_session
    for session in active_sessions:
  File "/Users/apple/Downloads/jumpserver-master/py3/lib/python3.6/site-packages/django/db/models/query.py", line 268, in __iter__
    self._fetch_all()
  File "/Users/apple/Downloads/jumpserver-master/py3/lib/python3.6/site-packages/django/db/models/query.py", line 1186, in _fetch_all
    self._result_cache = list(self._iterable_class(self))
  File "/Users/apple/Downloads/jumpserver-master/py3/lib/python3.6/site-packages/django/db/models/query.py", line 54, in __iter__
    results = compiler.execute_sql(chunked_fetch=self.chunked_fetch, chunk_size=self.chunk_size)
  File "/Users/apple/Downloads/jumpserver-master/py3/lib/python3.6/site-packages/django/db/models/sql/compiler.py", line 1063, in execute_sql
    cursor = self.connection.cursor()
  File "/Users/apple/Downloads/jumpserver-master/py3/lib/python3.6/site-packages/django/db/backends/base/base.py", line 255, in cursor
    return self._cursor()
  File "/Users/apple/Downloads/jumpserver-master/py3/lib/python3.6/site-packages/django/db/backends/base/base.py", line 232, in _cursor
    self.ensure_connection()
  File "/Users/apple/Downloads/jumpserver-master/py3/lib/python3.6/site-packages/django/db/backends/base/base.py", line 216, in ensure_connection
    self.connect()
  File "/Users/apple/Downloads/jumpserver-master/py3/lib/python3.6/site-packages/django/db/utils.py", line 89, in __exit__
    raise dj_exc_value.with_traceback(traceback) from exc_value
  File "/Users/apple/Downloads/jumpserver-master/py3/lib/python3.6/site-packages/django/db/backends/base/base.py", line 216, in ensure_connection
    self.connect()
  File "/Users/apple/Downloads/jumpserver-master/py3/lib/python3.6/site-packages/django/db/backends/base/base.py", line 194, in connect
    self.connection = self.get_new_connection(conn_params)
  File "/Users/apple/Downloads/jumpserver-master/py3/lib/python3.6/site-packages/django/db/backends/mysql/base.py", line 227, in get_new_connection
    return Database.connect(**conn_params)
  File "/Users/apple/Downloads/jumpserver-master/py3/lib/python3.6/site-packages/MySQLdb/__init__.py", line 85, in Connect
    return Connection(*args, **kwargs)
  File "/Users/apple/Downloads/jumpserver-master/py3/lib/python3.6/site-packages/MySQLdb/connections.py", line 208, in __init__
    super(Connection, self).__init__(*args, **kwargs2)
django.db.utils.OperationalError: (2006, "Can't connect to MySQL server on '101.201.198.218' (51)")
